Workbook

Sheet All Exposure Types
A1: Mean Heat Exposure Scores by ACS SOC Grouping | I1: Score Key
A2: ACS Occupation | B2: SOC 2-Digit | C2: Indoors, Uncontrolled | D2: Outdoors, Exposed | E2: Outdoors, Under Cover | F2: Very Hot or Very Cold | I2: Value | J2: Meaning
A3: =_xlfn.XLOOKUP('ACS-NAICS-SOC x-walk'!D2,'ACS-NAICS-SOC x-walk'!D:D,'ACS-NAICS-SOC x-walk'!D:D) -> Management, business, science, and arts occupations | B3: =_xlfn.XLOOKUP(A3,'ACS-NAICS-SOC x-walk'!D:D,'ACS-NAICS-SOC x-walk'!B:B) -> 11 | C3: =_xlfn.XLOOKUP(A3, 'Indoors, uncontrolled'!F:F, 'Indoors, uncontrolled'!H:H) -> 22.668161 | D3: =_xlfn.XLOOKUP(A3,'Outdoors, exposed'!F:F,'Outdoors, exposed'!H:H) -> 21.941573 | E3: =_xlfn.XLOOKUP(A3,'Outdoors, under cover'!F:F,'Outdoors, under cover'!H:H) -> 15.185897 | F3: =_xlfn.XLOOKUP(A3,'Very hot or very cold'!F:F,'Very hot or very cold'!H:H) -> 17.474157 | I3: =_xlfn.XLOOKUP('Context Scale'!A1,'Context Scale'!A:A, 'Context Scale'!A:A) -> 100 | J3: =_xlfn.XLOOKUP('Context Scale'!B1,'Context Scale'!B:B, 'Context Scale'!B:B) -> Every Day
A4: =_xlfn.XLOOKUP('ACS-NAICS-SOC x-walk'!D248,'ACS-NAICS-SOC x-walk'!D248,'ACS-NAICS-SOC x-walk'!D248) -> Service occupations | B4: =_xlfn.XLOOKUP(A4,'ACS-NAICS-SOC x-walk'!D:D,'ACS-NAICS-SOC x-walk'!B:B) -> 31 | C4: =_xlfn.XLOOKUP(A4, 'Indoors, uncontrolled'!F:F, 'Indoors, uncontrolled'!H:H) -> 27.072165 | D4: =_xlfn.XLOOKUP(A4,'Outdoors, exposed'!F:F,'Outdoors, exposed'!H:H) -> 38.360825 | E4: =_xlfn.XLOOKUP(A4,'Outdoors, under cover'!F:F,'Outdoors, under cover'!H:H) -> 23.753086 | F4: =_xlfn.XLOOKUP(A4,'Very hot or very cold'!F:F,'Very hot or very cold'!H:H) -> 34.195876 | I4: =_xlfn.XLOOKUP('Context Scale'!A2,'Context Scale'!A:A, 'Context Scale'!A:A) -> 75 | J4: =_xlfn.XLOOKUP('Context Scale'!B2,'Context Scale'!B:B, 'Context Scale'!B:B) -> Once a week or more, but not every day
A5: =_xlfn.XLOOKUP('ACS-NAICS-SOC x-walk'!D261,'ACS-NAICS-SOC x-walk'!D261,'ACS-NAICS-SOC x-walk'!D261) -> Natural resources, construction, and maintenance occupations | B5: =_xlfn.XLOOKUP(A5,'ACS-NAICS-SOC x-walk'!D:D,'ACS-NAICS-SOC x-walk'!B:B) -> 45 | C5: =_xlfn.XLOOKUP(A5, 'Indoors, uncontrolled'!F:F, 'Indoors, uncontrolled'!H:H) -> 59.666667 | D5: =_xlfn.XLOOKUP(A5,'Outdoors, exposed'!F:F,'Outdoors, exposed'!H:H) -> 71.04065 | E5: =_xlfn.XLOOKUP(A5,'Outdoors, under cover'!F:F,'Outdoors, under cover'!H:H) -> 41.276423 | F5: =_xlfn.XLOOKUP(A5,'Very hot or very cold'!F:F,'Very hot or very cold'!H:H) -> 65.390244 | I5: =_xlfn.XLOOKUP('Context Scale'!A3,'Context Scale'!A:A, 'Context Scale'!A:A) -> 50 | J5: =_xlfn.XLOOKUP('Context Scale'!B3,'Context Scale'!B:B, 'Context Scale'!B:B) -> Once a month or more, but not every week
A6: =_xlfn.XLOOKUP('ACS-NAICS-SOC x-walk'!D318,'ACS-NAICS-SOC x-walk'!D318,'ACS-NAICS-SOC x-walk'!D318) -> Production, transportation, and material moving occupations | B6: =_xlfn.XLOOKUP(A6,'ACS-NAICS-SOC x-walk'!D:D,'ACS-NAICS-SOC x-walk'!B:B) -> 51 | C6: =_xlfn.XLOOKUP(A6, 'Indoors, uncontrolled'!F:F, 'Indoors, uncontrolled'!H:H) -> 51.458065 | D6: =_xlfn.XLOOKUP(A6,'Outdoors, exposed'!F:F,'Outdoors, exposed'!H:H) -> 37.429487 | E6: =_xlfn.XLOOKUP(A6,'Outdoors, under cover'!F:F,'Outdoors, under cover'!H:H) -> 22.262821 | F6: =_xlfn.XLOOKUP(A6,'Very hot or very cold'!F:F,'Very hot or very cold'!H:H) -> 53.564103 | I6: =_xlfn.XLOOKUP('Context Scale'!A4,'Context Scale'!A:A, 'Context Scale'!A:A) -> 25 | J6: =_xlfn.XLOOKUP('Context Scale'!B4,'Context Scale'!B:B, 'Context Scale'!B:B) -> Once a year or more, but not every month
A7: =_xlfn.XLOOKUP('ACS-NAICS-SOC x-walk'!D322,'ACS-NAICS-SOC x-walk'!D322,'ACS-NAICS-SOC x-walk'!D322) -> Management, business, science, and arts occupations | B7: =_xlfn.XLOOKUP(A7,'ACS-NAICS-SOC x-walk'!D:D,'ACS-NAICS-SOC x-walk'!B:B) -> 11 | C7: =_xlfn.XLOOKUP(A7, 'Indoors, uncontrolled'!F:F, 'Indoors, uncontrolled'!H:H) -> 22.668161 | D7: =_xlfn.XLOOKUP(A7,'Outdoors, exposed'!F:F,'Outdoors, exposed'!H:H) -> 21.941573 | E7: =_xlfn.XLOOKUP(A7,'Outdoors, under cover'!F:F,'Outdoors, under cover'!H:H) -> 15.185897 | F7: =_xlfn.XLOOKUP(A7,'Very hot or very cold'!F:F,'Very hot or very cold'!H:H) -> 17.474157 | I7: =_xlfn.XLOOKUP('Context Scale'!A5,'Context Scale'!A:A, 'Context Scale'!A:A) -> 0 | J7: =_xlfn.XLOOKUP('Context Scale'!B5,'Context Scale'!B:B, 'Context Scale'!B:B) -> Never
A8: =_xlfn.XLOOKUP('ACS-NAICS-SOC x-walk'!D826,'ACS-NAICS-SOC x-walk'!D826,'ACS-NAICS-SOC x-walk'!D826) -> Sales and office occupations | B8: =_xlfn.XLOOKUP(A8,'ACS-NAICS-SOC x-walk'!D:D,'ACS-NAICS-SOC x-walk'!B:B) -> 43 | C8: =_xlfn.XLOOKUP(A8, 'Indoors, uncontrolled'!F:F, 'Indoors, uncontrolled'!H:H) -> 16.305556 | D8: =_xlfn.XLOOKUP(A8,'Outdoors, exposed'!F:F,'Outdoors, exposed'!H:H) -> 18.430556 | E8: =_xlfn.XLOOKUP(A8,'Outdoors, under cover'!F:F,'Outdoors, under cover'!H:H) -> 5.0980392 | F8: =_xlfn.XLOOKUP(A8,'Very hot or very cold'!F:F,'Very hot or very cold'!H:H) -> 17.152778
A12: Mean Heat Exposure Scores by ACS Industry Grouping
A13: ACS Industry | B13: NAICS 2-Digit | C13: Indoors, Uncontrolled | D13: Outdoors, Exposed | E13: Outdoors, Under Cover | F13: Very Hot or Very Cold
A14: =_xlfn.XLOOKUP('ACS-NAICS-SOC x-walk'!L2,'ACS-NAICS-SOC x-walk'!L2,'ACS-NAICS-SOC x-walk'!L2) -> Agriculture, Forestry, Fishing and Hunting, and Mining | B14: =_xlfn.XLOOKUP(A14,'ACS-NAICS-SOC x-walk'!L:L,'ACS-NAICS-SOC x-walk'!J:J) -> 11 | C14: =_xlfn.XLOOKUP(A14,'Indoors, uncontrolled'!J:J,'Indoors, uncontrolled'!M:M) -> 48.483871 | D14: =_xlfn.XLOOKUP(A14,'Outdoors, exposed'!J:J,'Outdoors, exposed'!M:M) -> 55.946237 | E14: =_xlfn.XLOOKUP(A14,'Outdoors, under cover'!J:J,'Outdoors, under cover'!M:M) -> 34.5 | F14: =_xlfn.XLOOKUP($A14,'Indoors, uncontrolled'!$J:$J,'Indoors, uncontrolled'!$M:$M) -> 48.483871
A15: =_xlfn.XLOOKUP('ACS-NAICS-SOC x-walk'!L3,'ACS-NAICS-SOC x-walk'!L3,'ACS-NAICS-SOC x-walk'!L3) -> Agriculture, Forestry, Fishing and Hunting, and Mining | B15: =_xlfn.XLOOKUP(A15,'ACS-NAICS-SOC x-walk'!L:L,'ACS-NAICS-SOC x-walk'!J:J) -> 11 | C15: =_xlfn.XLOOKUP(A15,'Indoors, uncontrolled'!J:J,'Indoors, uncontrolled'!M:M) -> 48.483871 | D15: =_xlfn.XLOOKUP(A15,'Outdoors, exposed'!J:J,'Outdoors, exposed'!M:M) -> 55.946237 | E15: =_xlfn.XLOOKUP(A15,'Outdoors, under cover'!J:J,'Outdoors, under cover'!M:M) -> 34.5 | F15: =_xlfn.XLOOKUP($A15,'Indoors, uncontrolled'!$J:$J,'Indoors, uncontrolled'!$M:$M) -> 48.483871
A16: =_xlfn.XLOOKUP('ACS-NAICS-SOC x-walk'!L4,'ACS-NAICS-SOC x-walk'!L4,'ACS-NAICS-SOC x-walk'!L4) -> Transportation and Warehousing, and Utilities | B16: =_xlfn.XLOOKUP(A16,'ACS-NAICS-SOC x-walk'!L:L,'ACS-NAICS-SOC x-walk'!J:J) -> 22 | C16: =_xlfn.XLOOKUP(A16,'Indoors, uncontrolled'!J:J,'Indoors, uncontrolled'!M:M) -> #N/A | D16: =_xlfn.XLOOKUP(A16,'Outdoors, exposed'!J:J,'Outdoors, exposed'!M:M) -> #N/A | E16: =_xlfn.XLOOKUP(A16,'Outdoors, under cover'!J:J,'Outdoors, under cover'!M:M) -> #N/A | F16: =_xlfn.XLOOKUP($A16,'Indoors, uncontrolled'!$J:$J,'Indoors, uncontrolled'!$M:$M) -> #N/A
A17: =_xlfn.XLOOKUP('ACS-NAICS-SOC x-walk'!L5,'ACS-NAICS-SOC x-walk'!L5,'ACS-NAICS-SOC x-walk'!L5) -> Construction | B17: =_xlfn.XLOOKUP(A17,'ACS-NAICS-SOC x-walk'!L:L,'ACS-NAICS-SOC x-walk'!J:J) -> 23 | C17: =_xlfn.XLOOKUP(A17,'Indoors, uncontrolled'!J:J,'Indoors, uncontrolled'!M:M) -> 57.934211 | D17: =_xlfn.XLOOKUP(A17,'Outdoors, exposed'!J:J,'Outdoors, exposed'!M:M) -> 61.434211 | E17: =_xlfn.XLOOKUP(A17,'Outdoors, under cover'!J:J,'Outdoors, under cover'!M:M) -> 38.146667 | F17: =_xlfn.XLOOKUP($A17,'Indoors, uncontrolled'!$J:$J,'Indoors, uncontrolled'!$M:$M) -> 57.934211
A18: =_xlfn.XLOOKUP('ACS-NAICS-SOC x-walk'!L6,'ACS-NAICS-SOC x-walk'!L6,'ACS-NAICS-SOC x-walk'!L6) -> Wholesale Trade | B18: =_xlfn.XLOOKUP(A18,'ACS-NAICS-SOC x-walk'!L:L,'ACS-NAICS-SOC x-walk'!J:J) -> 42 | C18: =_xlfn.XLOOKUP(A18,'Indoors, uncontrolled'!J:J,'Indoors, uncontrolled'!M:M) -> 53.857143 | D18: =_xlfn.XLOOKUP(A18,'Outdoors, exposed'!J:J,'Outdoors, exposed'!M:M) -> 61.704225 | E18: =_xlfn.XLOOKUP(A18,'Outdoors, under cover'!J:J,'Outdoors, under cover'!M:M) -> 35.235294 | F18: =_xlfn.XLOOKUP($A18,'Indoors, uncontrolled'!$J:$J,'Indoors, uncontrolled'!$M:$M) -> 53.857143
A19: =_xlfn.XLOOKUP('ACS-NAICS-SOC x-walk'!L7,'ACS-NAICS-SOC x-walk'!L7,'ACS-NAICS-SOC x-walk'!L7) -> Information | B19: =_xlfn.XLOOKUP(A19,'ACS-NAICS-SOC x-walk'!L:L,'ACS-NAICS-SOC x-walk'!J:J) -> 51 | C19: =_xlfn.XLOOKUP(A19,'Indoors, uncontrolled'!J:J,'Indoors, uncontrolled'!M:M) -> 11.518519 | D19: =_xlfn.XLOOKUP(A19,'Outdoors, exposed'!J:J,'Outdoors, exposed'!M:M) -> 7.962963 | E19: =_xlfn.XLOOKUP(A19,'Outdoors, under cover'!J:J,'Outdoors, under cover'!M:M) -> 6.8076923 | F19: =_xlfn.XLOOKUP($A19,'Indoors, uncontrolled'!$J:$J,'Indoors, uncontrolled'!$M:$M) -> 11.518519
A20: =_xlfn.XLOOKUP('ACS-NAICS-SOC x-walk'!L8,'ACS-NAICS-SOC x-walk'!L8,'ACS-NAICS-SOC x-walk'!L8) -> Finance and Insurance, and Real Estate, and Rental and Leasing | B20: =_xlfn.XLOOKUP(A20,'ACS-NAICS-SOC x-walk'!L:L,'ACS-NAICS-SOC x-walk'!J:J) -> 52 | C20: =_xlfn.XLOOKUP(A20,'Indoors, uncontrolled'!J:J,'Indoors, uncontrolled'!M:M) -> 11.96875 | D20: =_xlfn.XLOOKUP(A20,'Outdoors, exposed'!J:J,'Outdoors, exposed'!M:M) -> 14.75 | E20: =_xlfn.XLOOKUP(A20,'Outdoors, under cover'!J:J,'Outdoors, under cover'!M:M) -> 7.4333333 | F20: =_xlfn.XLOOKUP($A20,'Indoors, uncontrolled'!$J:$J,'Indoors, uncontrolled'!$M:$M) -> 11.96875
A21: =_xlfn.XLOOKUP('ACS-NAICS-SOC x-walk'!L9,'ACS-NAICS-SOC x-walk'!L9,'ACS-NAICS-SOC x-walk'!L9) -> Finance and Insurance, and Real Estate, and Rental and Leasing | B21: =_xlfn.XLOOKUP(A21,'ACS-NAICS-SOC x-walk'!L:L,'ACS-NAICS-SOC x-walk'!J:J) -> 52 | C21: =_xlfn.XLOOKUP(A21,'Indoors, uncontrolled'!J:J,'Indoors, uncontrolled'!M:M) -> 11.96875 | D21: =_xlfn.XLOOKUP(A21,'Outdoors, exposed'!J:J,'Outdoors, exposed'!M:M) -> 14.75 | E21: =_xlfn.XLOOKUP(A21,'Outdoors, under cover'!J:J,'Outdoors, under cover'!M:M) -> 7.4333333 | F21: =_xlfn.XLOOKUP($A21,'Indoors, uncontrolled'!$J:$J,'Indoors, uncontrolled'!$M:$M) -> 11.96875
A22: =_xlfn.XLOOKUP('ACS-NAICS-SOC x-walk'!L10,'ACS-NAICS-SOC x-walk'!L10,'ACS-NAICS-SOC x-walk'!L10) -> Professional, Scientific, and Management, and Administrative, and Waste Management Services | B22: =_xlfn.XLOOKUP(A22,'ACS-NAICS-SOC x-walk'!L:L,'ACS-NAICS-SOC x-walk'!J:J) -> 54 | C22: =_xlfn.XLOOKUP(A22,'Indoors, uncontrolled'!J:J,'Indoors, uncontrolled'!M:M) -> 28.163636 | D22: =_xlfn.XLOOKUP(A22,'Outdoors, exposed'!J:J,'Outdoors, exposed'!M:M) -> 37.072727 | E22: =_xlfn.XLOOKUP(A22,'Outdoors, under cover'!J:J,'Outdoors, under cover'!M:M) -> 19.346154 | F22: =_xlfn.XLOOKUP($A22,'Indoors, uncontrolled'!$J:$J,'Indoors, uncontrolled'!$M:$M) -> 28.163636
A23: =_xlfn.XLOOKUP('ACS-NAICS-SOC x-walk'!L11,'ACS-NAICS-SOC x-walk'!L11,'ACS-NAICS-SOC x-walk'!L11) -> Professional, Scientific, and Management, and Administrative, and Waste Management Services | B23: =_xlfn.XLOOKUP(A23,'ACS-NAICS-SOC x-walk'!L:L,'ACS-NAICS-SOC x-walk'!J:J) -> 54 | C23: =_xlfn.XLOOKUP(A23,'Indoors, uncontrolled'!J:J,'Indoors, uncontrolled'!M:M) -> 28.163636 | D23: =_xlfn.XLOOKUP(A23,'Outdoors, exposed'!J:J,'Outdoors, exposed'!M:M) -> 37.072727 | E23: =_xlfn.XLOOKUP(A23,'Outdoors, under cover'!J:J,'Outdoors, under cover'!M:M) -> 19.346154 | F23: =_xlfn.XLOOKUP($A23,'Indoors, uncontrolled'!$J:$J,'Indoors, uncontrolled'!$M:$M) -> 28.163636
A24: =_xlfn.XLOOKUP('ACS-NAICS-SOC x-walk'!L12,'ACS-NAICS-SOC x-walk'!L12,'ACS-NAICS-SOC x-walk'!L12) -> Professional, Scientific, and Management, and Administrative, and Waste Management Services | B24: =_xlfn.XLOOKUP(A24,'ACS-NAICS-SOC x-walk'!L:L,'ACS-NAICS-SOC x-walk'!J:J) -> 54 | C24: =_xlfn.XLOOKUP(A24,'Indoors, uncontrolled'!J:J,'Indoors, uncontrolled'!M:M) -> 28.163636 | D24: =_xlfn.XLOOKUP(A24,'Outdoors, exposed'!J:J,'Outdoors, exposed'!M:M) -> 37.072727 | E24: =_xlfn.XLOOKUP(A24,'Outdoors, under cover'!J:J,'Outdoors, under cover'!M:M) -> 19.346154 | F24: =_xlfn.XLOOKUP($A24,'Indoors, uncontrolled'!$J:$J,'Indoors, uncontrolled'!$M:$M) -> 28.163636
A25: =_xlfn.XLOOKUP('ACS-NAICS-SOC x-walk'!L13,'ACS-NAICS-SOC x-walk'!L13,'ACS-NAICS-SOC x-walk'!L13) -> Professional, Scientific, and Management, and Administrative, and Waste Management Services | B25: =_xlfn.XLOOKUP(A25,'ACS-NAICS-SOC x-walk'!L:L,'ACS-NAICS-SOC x-walk'!J:J) -> 54 | C25: =_xlfn.XLOOKUP(A25,'Indoors, uncontrolled'!J:J,'Indoors, uncontrolled'!M:M) -> 28.163636 | D25: =_xlfn.XLOOKUP(A25,'Outdoors, exposed'!J:J,'Outdoors, exposed'!M:M) -> 37.072727 | E25: =_xlfn.XLOOKUP(A25,'Outdoors, under cover'!J:J,'Outdoors, under cover'!M:M) -> 19.346154 | F25: =_xlfn.XLOOKUP($A25,'Indoors, uncontrolled'!$J:$J,'Indoors, uncontrolled'!$M:$M) -> 28.163636
... A28: =_xlfn.XLOOKUP('ACS-NAICS-SOC x-walk'!L16,'ACS-NAICS-SOC x-walk'!L16,'ACS-NAICS-SOC x-walk'!L16) -> Arts, Entertainment, and Recreation, and Accommodation and Food Services, and Retail Trade | B28: =_xlfn.XLOOKUP(A28,'ACS-NAICS-SOC x-walk'!L:L,'ACS-NAICS-SOC x-walk'!J:J) -> 71 | C28: =_xlfn.XLOOKUP(A28,'Indoors, uncontrolled'!J:J,'Indoors, uncontrolled'!M:M) -> 22.883721 | D28: =_xlfn.XLOOKUP(A28,'Outdoors, exposed'!J:J,'Outdoors, exposed'!M:M) -> 28.418605 | E28: =_xlfn.XLOOKUP(A28,'Outdoors, under cover'!J:J,'Outdoors, under cover'!M:M) -> 15.820513 | F28: =_xlfn.XLOOKUP($A28,'Indoors, uncontrolled'!$J:$J,'Indoors, uncontrolled'!$M:$M) -> 22.883721
A29: Manufacturing | B29: 31 | C29: =_xlfn.XLOOKUP(A29,'Indoors, uncontrolled'!J:J,'Indoors, uncontrolled'!M:M) -> 49.539823 | D29: =_xlfn.XLOOKUP(A29,'Outdoors, exposed'!J:J,'Outdoors, exposed'!M:M) -> 22.699115 | E29: =_xlfn.XLOOKUP(A29,'Outdoors, under cover'!J:J,'Outdoors, under cover'!M:M) -> 14.71028 | F29: =_xlfn.XLOOKUP($A29,'Indoors, uncontrolled'!$J:$J,'Indoors, uncontrolled'!$M:$M) -> 49.539823
A30: Manufacturing | B30: 32 | C30: =_xlfn.XLOOKUP(A30,'Indoors, uncontrolled'!J:J,'Indoors, uncontrolled'!M:M) -> 49.539823 | D30: =_xlfn.XLOOKUP(A30,'Outdoors, exposed'!J:J,'Outdoors, exposed'!M:M) -> 22.699115 | E30: =_xlfn.XLOOKUP(A30,'Outdoors, under cover'!J:J,'Outdoors, under cover'!M:M) -> 14.71028 | F30: =_xlfn.XLOOKUP($A30,'Indoors, uncontrolled'!$J:$J,'Indoors, uncontrolled'!$M:$M) -> 49.539823
A31: Manufacturing | B31: 33 | C31: =_xlfn.XLOOKUP(A31,'Indoors, uncontrolled'!J:J,'Indoors, uncontrolled'!M:M) -> 49.539823 | D31: =_xlfn.XLOOKUP(A31,'Outdoors, exposed'!J:J,'Outdoors, exposed'!M:M) -> 22.699115 | E31: =_xlfn.XLOOKUP(A31,'Outdoors, under cover'!J:J,'Outdoors, under cover'!M:M) -> 14.71028 | F31: =_xlfn.XLOOKUP($A31,'Indoors, uncontrolled'!$J:$J,'Indoors, uncontrolled'!$M:$M) -> 49.539823

Sheet Indoors, uncontrolled
A1: Browse by Work Context
A2: Indoors, Not Environmentally Controlled
A4: Context | B4: Job Zone | C4: SOC Occupation Code | D4: SOC 2-Digit Code | E4: SOC 6-Digit Description | F4: ACS Occupation Description | G4: Aggregate ACS Occupation Context Score | H4: ACS Occupation Category Mean Context Score | I4: NAICS Code | J4: ACS Industry Description | K4: NAICS Description | L4: Aggregate Industry Context Score | M4: ACS Industry Category Mean Context Score
A5: 47 | B5: 3 | C5: 47-1011 | D5: =VALUE(LEFT(C5,2)) -> 47 | E5: First-Line Supervisors of Construction Trades and Extraction Workers | F5: {=_xlfn.IFS( AND(D5>=11, D5<=29), "Management, business, science, and arts occupations", AND(D5>=31, D5<=39), "Service occupations", AND(D5>=41, D5<=43), "Sales and office occupations", AND(D5>=51, D5<=53), "Production, transportation, and material moving occupations", AND(D5>=45, D5<=49), "Natural resources, construction, and maintenance occupations", TRUE, "Not applicable to study area" )} -> Natural resources, construction, and maintenance occupations | G5: =SUMIF(F:F, F5, A:A) -> 7339 | H5: =AVERAGEIF(F:F, F5, A:A) -> 59.666667 | I5: =_xlfn.XLOOKUP($C5,'NAICS-SOC-CIP x-walk'!C:C, 'NAICS-SOC-CIP x-walk'!H:H) -> 21, 22 | J5: =_xlfn.XLOOKUP(K5,'ACS-NAICS-SOC x-walk'!K:K,'ACS-NAICS-SOC x-walk'!L:L) -> Agriculture, Forestry, Fishing and Hunting, and Mining | K5: =_xlfn.XLOOKUP($C5,'NAICS-SOC-CIP x-walk'!$C:$C, 'NAICS-SOC-CIP x-walk'!I:I) -> Mining, Quarrying, and Oil and Gas Extraction, Utilities | L5: =SUMIF(K:K, K5, A:A) -> 4509 | M5: =AVERAGEIF(K:K, K5, A:A) -> 48.483871
A6: 61 | B6: 3 | C6: 47-1011 | D6: =VALUE(LEFT(C6,2)) -> 47 | E6: Solar Energy Installation Managers | F6: {=_xlfn.IFS( AND(D6>=11, D6<=29), "Management, business, science, and arts occupations", AND(D6>=31, D6<=39), "Service occupations", AND(D6>=41, D6<=43), "Sales and office occupations", AND(D6>=51, D6<=53), "Production, transportation, and material moving occupations", AND(D6>=45, D6<=49), "Natural resources, construction, and maintenance occupations", TRUE, "Not applicable to study area" )} -> Natural resources, construction, and maintenance occupations | G6: =SUMIF(F:F, F6, A:A) -> 7339 | H6: =AVERAGEIF(F:F, F6, A:A) -> 59.666667 | I6: =_xlfn.XLOOKUP($C6,'NAICS-SOC-CIP x-walk'!C:C, 'NAICS-SOC-CIP x-walk'!H:H) -> 21, 22 | J6: =_xlfn.XLOOKUP(K6,'ACS-NAICS-SOC x-walk'!K:K,'ACS-NAICS-SOC x-walk'!L:L) -> Agriculture, Forestry, Fishing and Hunting, and Mining | K6: =_xlfn.XLOOKUP($C6,'NAICS-SOC-CIP x-walk'!$C:$C, 'NAICS-SOC-CIP x-walk'!I:I) -> Mining, Quarrying, and Oil and Gas Extraction, Utilities | L6: =SUMIF(K:K, K6, A:A) -> 4509 | M6: =AVERAGEIF(K:K, K6, A:A) -> 48.483871
A7: 73 | B7: 1-2 | C7: 47-2011 | D7: =VALUE(LEFT(C7,2)) -> 47 | E7: Boilermakers | F7: {=_xlfn.IFS( AND(D7>=11, D7<=29), "Management, business, science, and arts occupations", AND(D7>=31, D7<=39), "Service occupations", AND(D7>=41, D7<=43), "Sales and office occupations", AND(D7>=51, D7<=53), "Production, transportation, and material moving occupations", AND(D7>=45, D7<=49), "Natural resources, construction, and maintenance occupations", TRUE, "Not applicable to study area" )} -> Natural resources, construction, and maintenance occupations | G7: =SUMIF(F:F, F7, A:A) -> 7339 | H7: =AVERAGEIF(F:F, F7, A:A) -> 59.666667 | I7: =_xlfn.XLOOKUP($C7,'NAICS-SOC-CIP x-walk'!C:C, 'NAICS-SOC-CIP x-walk'!H:H) -> 23 | J7: =_xlfn.XLOOKUP(K7,'ACS-NAICS-SOC x-walk'!K:K,'ACS-NAICS-SOC x-walk'!L:L) -> Construction | K7: =_xlfn.XLOOKUP($C7,'NAICS-SOC-CIP x-walk'!$C:$C, 'NAICS-SOC-CIP x-walk'!I:I) -> Construction | L7: =SUMIF(K:K, K7, A:A) -> 4403 | M7: =AVERAGEIF(K:K, K7, A:A) -> 57.934211
A8: 74 | B8: 1-2 | C8: 47-2021 | D8: =VALUE(LEFT(C8,2)) -> 47 | E8: Brickmasons and Blockmasons | F8: {=_xlfn.IFS( AND(D8>=11, D8<=29), "Management, business, science, and arts occupations", AND(D8>=31, D8<=39), "Service occupations", AND(D8>=41, D8<=43), "Sales and office occupations", AND(D8>=51, D8<=53), "Production, transportation, and material moving occupations", AND(D8>=45, D8<=49), "Natural resources, construction, and maintenance occupations", TRUE, "Not applicable to study area" )} -> Natural resources, construction, and maintenance occupations | G8: =SUMIF(F:F, F8, A:A) -> 7339 | H8: =AVERAGEIF(F:F, F8, A:A) -> 59.666667 | I8: =_xlfn.XLOOKUP($C8,'NAICS-SOC-CIP x-walk'!C:C, 'NAICS-SOC-CIP x-walk'!H:H) -> 23 | J8: =_xlfn.XLOOKUP(K8,'ACS-NAICS-SOC x-walk'!K:K,'ACS-NAICS-SOC x-walk'!L:L) -> Construction | K8: =_xlfn.XLOOKUP($C8,'NAICS-SOC-CIP x-walk'!$C:$C, 'NAICS-SOC-CIP x-walk'!I:I) -> Construction | L8: =SUMIF(K:K, K8, A:A) -> 4403 | M8: =AVERAGEIF(K:K, K8, A:A) -> 57.934211
A9: 29 | B9: 1-2 | C9: 47-2022 | D9: =VALUE(LEFT(C9,2)) -> 47 | E9: Stonemasons | F9: {=_xlfn.IFS( AND(D9>=11, D9<=29), "Management, business, science, and arts occupations", AND(D9>=31, D9<=39), "Service occupations", AND(D9>=41, D9<=43), "Sales and office occupations", AND(D9>=51, D9<=53), "Production, transportation, and material moving occupations", AND(D9>=45, D9<=49), "Natural resources, construction, and maintenance occupations", TRUE, "Not applicable to study area" )} -> Natural resources, construction, and maintenance occupations | G9: =SUMIF(F:F, F9, A:A) -> 7339 | H9: =AVERAGEIF(F:F, F9, A:A) -> 59.666667 | I9: =_xlfn.XLOOKUP($C9,'NAICS-SOC-CIP x-walk'!C:C, 'NAICS-SOC-CIP x-walk'!H:H) -> 23 | J9: =_xlfn.XLOOKUP(K9,'ACS-NAICS-SOC x-walk'!K:K,'ACS-NAICS-SOC x-walk'!L:L) -> Construction | K9: =_xlfn.XLOOKUP($C9,'NAICS-SOC-CIP x-walk'!$C:$C, 'NAICS-SOC-CIP x-walk'!I:I) -> Construction | L9: =SUMIF(K:K, K9, A:A) -> 4403 | M9: =AVERAGEIF(K:K, K9, A:A) -> 57.934211
A10: 43 | B10: 1-2 | C10: 47-2031 | D10: =VALUE(LEFT(C10,2)) -> 47 | E10: Carpenters | F10: {=_xlfn.IFS( AND(D10>=11, D10<=29), "Management, business, science, and arts occupations", AND(D10>=31, D10<=39), "Service occupations", AND(D10>=41, D10<=43), "Sales and office occupations", AND(D10>=51, D10<=53), "Production, transportation, and material moving occupations", AND(D10>=45, D10<=49), "Natural resources, construction, and maintenance occupations", TRUE, "Not applicable to study area" )} -> Natural resources, construction, and maintenance occupations | G10: =SUMIF(F:F, F10, A:A) -> 7339 | H10: =AVERAGEIF(F:F, F10, A:A) -> 59.666667 | I10: =_xlfn.XLOOKUP($C10,'NAICS-SOC-CIP x-walk'!C:C, 'NAICS-SOC-CIP x-walk'!H:H) -> 23 | J10: =_xlfn.XLOOKUP(K10,'ACS-NAICS-SOC x-walk'!K:K,'ACS-NAICS-SOC x-walk'!L:L) -> Construction | K10: =_xlfn.XLOOKUP($C10,'NAICS-SOC-CIP x-walk'!$C:$C, 'NAICS-SOC-CIP x-walk'!I:I) -> Construction | L10: =SUMIF(K:K, K10, A:A) -> 4403 | M10: =AVERAGEIF(K:K, K10, A:A) -> 57.934211
A11: 42 | B11: 1-2 | C11: 47-2041 | D11: =VALUE(LEFT(C11,2)) -> 47 | E11: Carpet Installers | F11: {=_xlfn.IFS( AND(D11>=11, D11<=29), "Management, business, science, and arts occupations", AND(D11>=31, D11<=39), "Service occupations", AND(D11>=41, D11<=43), "Sales and office occupations", AND(D11>=51, D11<=53), "Production, transportation, and material moving occupations", AND(D11>=45, D11<=49), "Natural resources, construction, and maintenance occupations", TRUE, "Not applicable to study area" )} -> Natural resources, construction, and maintenance occupations | G11: =SUMIF(F:F, F11, A:A) -> 7339 | H11: =AVERAGEIF(F:F, F11, A:A) -> 59.666667 | I11: =_xlfn.XLOOKUP($C11,'NAICS-SOC-CIP x-walk'!C:C, 'NAICS-SOC-CIP x-walk'!H:H) -> 23 | J11: =_xlfn.XLOOKUP(K11,'ACS-NAICS-SOC x-walk'!K:K,'ACS-NAICS-SOC x-walk'!L:L) -> Construction | K11: =_xlfn.XLOOKUP($C11,'NAICS-SOC-CIP x-walk'!$C:$C, 'NAICS-SOC-CIP x-walk'!I:I) -> Construction | L11: =SUMIF(K:K, K11, A:A) -> 4403 | M11: =AVERAGEIF(K:K, K11, A:A) -> 57.934211
A12: 57 | B12: 1-2 | C12: 47-2042 | D12: =VALUE(LEFT(C12,2)) -> 47 | E12: Floor Layers, Except Carpet, Wood, and Hard Tiles | F12: {=_xlfn.IFS( AND(D12>=11, D12<=29), "Management, business, science, and arts occupations", AND(D12>=31, D12<=39), "Service occupations", AND(D12>=41, D12<=43), "Sales and office occupations", AND(D12>=51, D12<=53), "Production, transportation, and material moving occupations", AND(D12>=45, D12<=49), "Natural resources, construction, and maintenance occupations", TRUE, "Not applicable to study area" )} -> Natural resources, construction, and maintenance occupations | G12: =SUMIF(F:F, F12, A:A) -> 7339 | H12: =AVERAGEIF(F:F, F12, A:A) -> 59.666667 | I12: =_xlfn.XLOOKUP($C12,'NAICS-SOC-CIP x-walk'!C:C, 'NAICS-SOC-CIP x-walk'!H:H) -> 23 | J12: =_xlfn.XLOOKUP(K12,'ACS-NAICS-SOC x-walk'!K:K,'ACS-NAICS-SOC x-walk'!L:L) -> Construction | K12: =_xlfn.XLOOKUP($C12,'NAICS-SOC-CIP x-walk'!$C:$C, 'NAICS-SOC-CIP x-walk'!I:I) -> Construction | L12: =SUMIF(K:K, K12, A:A) -> 4403 | M12: =AVERAGEIF(K:K, K12, A:A) -> 57.934211
A13: 44 | B13: 1-2 | C13: 47-2043 | D13: =VALUE(LEFT(C13,2)) -> 47 | E13: Floor Sanders and Finishers | F13: {=_xlfn.IFS( AND(D13>=11, D13<=29), "Management, business, science, and arts occupations", AND(D13>=31, D13<=39), "Service occupations", AND(D13>=41, D13<=43), "Sales and office occupations", AND(D13>=51, D13<=53), "Production, transportation, and material moving occupations", AND(D13>=45, D13<=49), "Natural resources, construction, and maintenance occupations", TRUE, "Not applicable to study area" )} -> Natural resources, construction, and maintenance occupations | G13: =SUMIF(F:F, F13, A:A) -> 7339 | H13: =AVERAGEIF(F:F, F13, A:A) -> 59.666667 | I13: =_xlfn.XLOOKUP($C13,'NAICS-SOC-CIP x-walk'!C:C, 'NAICS-SOC-CIP x-walk'!H:H) -> 23 | J13: =_xlfn.XLOOKUP(K13,'ACS-NAICS-SOC x-walk'!K:K,'ACS-NAICS-SOC x-walk'!L:L) -> Construction | K13: =_xlfn.XLOOKUP($C13,'NAICS-SOC-CIP x-walk'!$C:$C, 'NAICS-SOC-CIP x-walk'!I:I) -> Construction | L13: =SUMIF(K:K, K13, A:A) -> 4403 | M13: =AVERAGEIF(K:K, K13, A:A) -> 57.934211
A14: 47 | B14: 1-2 | C14: 47-2044 | D14: =VALUE(LEFT(C14,2)) -> 47 | E14: Tile and Stone Setters | F14: {=_xlfn.IFS( AND(D14>=11, D14<=29), "Management, business, science, and arts occupations", AND(D14>=31, D14<=39), "Service occupations", AND(D14>=41, D14<=43), "Sales and office occupations", AND(D14>=51, D14<=53), "Production, transportation, and material moving occupations", AND(D14>=45, D14<=49), "Natural resources, construction, and maintenance occupations", TRUE, "Not applicable to study area" )} -> Natural resources, construction, and maintenance occupations | G14: =SUMIF(F:F, F14, A:A) -> 7339 | H14: =AVERAGEIF(F:F, F14, A:A) -> 59.666667 | I14: =_xlfn.XLOOKUP($C14,'NAICS-SOC-CIP x-walk'!C:C, 'NAICS-SOC-CIP x-walk'!H:H) -> 23 | J14: =_xlfn.XLOOKUP(K14,'ACS-NAICS-SOC x-walk'!K:K,'ACS-NAICS-SOC x-walk'!L:L) -> Construction | K14: =_xlfn.XLOOKUP($C14,'NAICS-SOC-CIP x-walk'!$C:$C, 'NAICS-SOC-CIP x-walk'!I:I) -> Construction | L14: =SUMIF(K:K, K14, A:A) -> 4403 | M14: =AVERAGEIF(K:K, K14, A:A) -> 57.934211
A15: 38 | B15: 1-2 | C15: 47-2051 | D15: =VALUE(LEFT(C15,2)) -> 47 | E15: Cement Masons and Concrete Finishers | F15: {=_xlfn.IFS( AND(D15>=11, D15<=29), "Management, business, science, and arts occupations", AND(D15>=31, D15<=39), "Service occupations", AND(D15>=41, D15<=43), "Sales and office occupations", AND(D15>=51, D15<=53), "Production, transportation, and material moving occupations", AND(D15>=45, D15<=49), "Natural resources, construction, and maintenance occupations", TRUE, "Not applicable to study area" )} -> Natural resources, construction, and maintenance occupations | G15: =SUMIF(F:F, F15, A:A) -> 7339 | H15: =AVERAGEIF(F:F, F15, A:A) -> 59.666667 | I15: =_xlfn.XLOOKUP($C15,'NAICS-SOC-CIP x-walk'!C:C, 'NAICS-SOC-CIP x-walk'!H:H) -> 23 | J15: =_xlfn.XLOOKUP(K15,'ACS-NAICS-SOC x-walk'!K:K,'ACS-NAICS-SOC x-walk'!L:L) -> Construction | K15: =_xlfn.XLOOKUP($C15,'NAICS-SOC-CIP x-walk'!$C:$C, 'NAICS-SOC-CIP x-walk'!I:I) -> Construction | L15: =SUMIF(K:K, K15, A:A) -> 4403 | M15: =AVERAGEIF(K:K, K15, A:A) -> 57.934211
A16: 54 | B16: 1-2 | C16: 47-2053 | D16: =VALUE(LEFT(C16,2)) -> 47 | E16: Terrazzo Workers and Finishers | F16: {=_xlfn.IFS( AND(D16>=11, D16<=29), "Management, business, science, and arts occupations", AND(D16>=31, D16<=39), "Service occupations", AND(D16>=41, D16<=43), "Sales and office occupations", AND(D16>=51, D16<=53), "Production, transportation, and material moving occupations", AND(D16>=45, D16<=49), "Natural resources, construction, and maintenance occupations", TRUE, "Not applicable to study area" )} -> Natural resources, construction, and maintenance occupations | G16: =SUMIF(F:F, F16, A:A) -> 7339 | H16: =AVERAGEIF(F:F, F16, A:A) -> 59.666667 | I16: =_xlfn.XLOOKUP($C16,'NAICS-SOC-CIP x-walk'!C:C, 'NAICS-SOC-CIP x-walk'!H:H) -> 23 | J16: =_xlfn.XLOOKUP(K16,'ACS-NAICS-SOC x-walk'!K:K,'ACS-NAICS-SOC x-walk'!L:L) -> Construction | K16: =_xlfn.XLOOKUP($C16,'NAICS-SOC-CIP x-walk'!$C:$C, 'NAICS-SOC-CIP x-walk'!I:I) -> Construction | L16: =SUMIF(K:K, K16, A:A) -> 4403 | M16: =AVERAGEIF(K:K, K16, A:A) -> 57.934211
A17: 57 | B17: 1-2 | C17: 47-2061 | D17: =VALUE(LEFT(C17,2)) -> 47 | E17: Construction Laborers | F17: {=_xlfn.IFS( AND(D17>=11, D17<=29), "Management, business, science, and arts occupations", AND(D17>=31, D17<=39), "Service occupations", AND(D17>=41, D17<=43), "Sales and office occupations", AND(D17>=51, D17<=53), "Production, transportation, and material moving occupations", AND(D17>=45, D17<=49), "Natural resources, construction, and maintenance occupations", TRUE, "Not applicable to study area" )} -> Natural resources, construction, and maintenance occupations | G17: =SUMIF(F:F, F17, A:A) -> 7339 | H17: =AVERAGEIF(F:F, F17, A:A) -> 59.666667 | I17: =_xlfn.XLOOKUP($C17,'NAICS-SOC-CIP x-walk'!C:C, 'NAICS-SOC-CIP x-walk'!H:H) -> 23 | J17: =_xlfn.XLOOKUP(K17,'ACS-NAICS-SOC x-walk'!K:K,'ACS-NAICS-SOC x-walk'!L:L) -> Construction | K17: =_xlfn.XLOOKUP($C17,'NAICS-SOC-CIP x-walk'!$C:$C, 'NAICS-SOC-CIP x-walk'!I:I) -> Construction | L17: =SUMIF(K:K, K17, A:A) -> 4403 | M17: =AVERAGEIF(K:K, K17, A:A) -> 57.934211
A18: 31 | B18: 1-2 | C18: 47-2071 | D18: =VALUE(LEFT(C18,2)) -> 47 | E18: Paving, Surfacing, and Tamping Equipment Operators | F18: {=_xlfn.IFS( AND(D18>=11, D18<=29), "Management, business, science, and arts occupations", AND(D18>=31, D18<=39), "Service occupations", AND(D18>=41, D18<=43), "Sales and office occupations", AND(D18>=51, D18<=53), "Production, transportation, and material moving occupations", AND(D18>=45, D18<=49), "Natural resources, construction, and maintenance occupations", TRUE, "Not applicable to study area" )} -> Natural resources, construction, and maintenance occupations | G18: =SUMIF(F:F, F18, A:A) -> 7339 | H18: =AVERAGEIF(F:F, F18, A:A) -> 59.666667 | I18: =_xlfn.XLOOKUP($C18,'NAICS-SOC-CIP x-walk'!C:C, 'NAICS-SOC-CIP x-walk'!H:H) -> 23 | J18: =_xlfn.XLOOKUP(K18,'ACS-NAICS-SOC x-walk'!K:K,'ACS-NAICS-SOC x-walk'!L:L) -> Construction | K18: =_xlfn.XLOOKUP($C18,'NAICS-SOC-CIP x-walk'!$C:$C, 'NAICS-SOC-CIP x-walk'!I:I) -> Construction | L18: =SUMIF(K:K, K18, A:A) -> 4403 | M18: =AVERAGEIF(K:K, K18, A:A) -> 57.934211
... A22: 66 | B22: 1-2 | C22: 47-2082 | D22: =VALUE(LEFT(C22,2)) -> 47 | E22: Tapers | F22: {=_xlfn.IFS( AND(D22>=11, D22<=29), "Management, business, science, and arts occupations", AND(D22>=31, D22<=39), "Service occupations", AND(D22>=41, D22<=43), "Sales and office occupations", AND(D22>=51, D22<=53), "Production, transportation, and material moving occupations", AND(D22>=45, D22<=49), "Natural resources, construction, and maintenance occupations", TRUE, "Not applicable to study area" )} -> Natural resources, construction, and maintenance occupations | G22: =SUMIF(F:F, F22, A:A) -> 7339 | H22: =AVERAGEIF(F:F, F22, A:A) -> 59.666667 | I22: =_xlfn.XLOOKUP($C22,'NAICS-SOC-CIP x-walk'!C:C, 'NAICS-SOC-CIP x-walk'!H:H) -> 23 | J22: =_xlfn.XLOOKUP(K22,'ACS-NAICS-SOC x-walk'!K:K,'ACS-NAICS-SOC x-walk'!L:L) -> Construction | K22: =_xlfn.XLOOKUP($C22,'NAICS-SOC-CIP x-walk'!$C:$C, 'NAICS-SOC-CIP x-walk'!I:I) -> Construction | L22: =SUMIF(K:K, K22, A:A) -> 4403 | M22: =AVERAGEIF(K:K, K22, A:A) -> 57.934211
A23: 81 | B23: 3 | C23: 47-2111 | D23: =VALUE(LEFT(C23,2)) -> 47 | E23: Electricians | F23: {=_xlfn.IFS( AND(D23>=11, D23<=29), "Management, business, science, and arts occupations", AND(D23>=31, D23<=39), "Service occupations", AND(D23>=41, D23<=43), "Sales and office occupations", AND(D23>=51, D23<=53), "Production, transportation, and material moving occupations", AND(D23>=45, D23<=49), "Natural resources, construction, and maintenance occupations", TRUE, "Not applicable to study area" )} -> Natural resources, construction, and maintenance occupations | G23: =SUMIF(F:F, F23, A:A) -> 7339 | H23: =AVERAGEIF(F:F, F23, A:A) -> 59.666667 | I23: =_xlfn.XLOOKUP($C23,'NAICS-SOC-CIP x-walk'!C:C, 'NAICS-SOC-CIP x-walk'!H:H) -> 23 | J23: =_xlfn.XLOOKUP(K23,'ACS-NAICS-SOC x-walk'!K:K,'ACS-NAICS-SOC x-walk'!L:L) -> Construction | K23: =_xlfn.XLOOKUP($C23,'NAICS-SOC-CIP x-walk'!$C:$C, 'NAICS-SOC-CIP x-walk'!I:I) -> Construction | L23: =SUMIF(K:K, K23, A:A) -> 4403 | M23: =AVERAGEIF(K:K, K23, A:A) -> 57.934211
A24: 72 | B24: 1-2 | C24: 47-2121 | D24: =VALUE(LEFT(C24,2)) -> 47 | E24: Glaziers | F24: {=_xlfn.IFS( AND(D24>=11, D24<=29), "Management, business, science, and arts occupations", AND(D24>=31, D24<=39), "Service occupations", AND(D24>=41, D24<=43), "Sales and office occupations", AND(D24>=51, D24<=53), "Production, transportation, and material moving occupations", AND(D24>=45, D24<=49), "Natural resources, construction, and maintenance occupations", TRUE, "Not applicable to study area" )} -> Natural resources, construction, and maintenance occupations | G24: =SUMIF(F:F, F24, A:A) -> 7339 | H24: =AVERAGEIF(F:F, F24, A:A) -> 59.666667 | I24: =_xlfn.XLOOKUP($C24,'NAICS-SOC-CIP x-walk'!C:C, 'NAICS-SOC-CIP x-walk'!H:H) -> 23 | J24: =_xlfn.XLOOKUP(K24,'ACS-NAICS-SOC x-walk'!K:K,'ACS-NAICS-SOC x-walk'!L:L) -> Construction | K24: =_xlfn.XLOOKUP($C24,'NAICS-SOC-CIP x-walk'!$C:$C, 'NAICS-SOC-CIP x-walk'!I:I) -> Construction | L24: =SUMIF(K:K, K24, A:A) -> 4403 | M24: =AVERAGEIF(K:K, K24, A:A) -> 57.934211
A25: 72 | B25: 1-2 | C25: 47-2131 | D25: =VALUE(LEFT(C25,2)) -> 47 | E25: Insulation Workers, Floor, Ceiling, and Wall | F25: {=_xlfn.IFS( AND(D25>=11, D25<=29), "Management, business, science, and arts occupations", AND(D25>=31, D25<=39), "Service occupations", AND(D25>=41, D25<=43), "Sales and office occupations", AND(D25>=51, D25<=53), "Production, transportation, and material moving occupations", AND(D25>=45, D25<=49), "Natural resources, construction, and maintenance occupations", TRUE, "Not applicable to study area" )} -> Natural resources, construction, and maintenance occupations | G25: =SUMIF(F:F, F25, A:A) -> 7339 | H25: =AVERAGEIF(F:F, F25, A:A) -> 59.666667 | I25: =_xlfn.XLOOKUP($C25,'NAICS-SOC-CIP x-walk'!C:C, 'NAICS-SOC-CIP x-walk'!H:H) -> 23 | J25: =_xlfn.XLOOKUP(K25,'ACS-NAICS-SOC x-walk'!K:K,'ACS-NAICS-SOC x-walk'!L:L) -> Construction | K25: =_xlfn.XLOOKUP($C25,'NAICS-SOC-CIP x-walk'!$C:$C, 'NAICS-SOC-CIP x-walk'!I:I) -> Construction | L25: =SUMIF(K:K, K25, A:A) -> 4403 | M25: =AVERAGEIF(K:K, K25, A:A) -> 57.934211
A26: 74 | B26: 1-2 | C26: 47-2132 | D26: =VALUE(LEFT(C26,2)) -> 47 | E26: Insulation Workers, Mechanical | F26: {=_xlfn.IFS( AND(D26>=11, D26<=29), "Management, business, science, and arts occupations", AND(D26>=31, D26<=39), "Service occupations", AND(D26>=41, D26<=43), "Sales and office occupations", AND(D26>=51, D26<=53), "Production, transportation, and material moving occupations", AND(D26>=45, D26<=49), "Natural resources, construction, and maintenance occupations", TRUE, "Not applicable to study area" )} -> Natural resources, construction, and maintenance occupations | G26: =SUMIF(F:F, F26, A:A) -> 7339 | H26: =AVERAGEIF(F:F, F26, A:A) -> 59.666667 | I26: =_xlfn.XLOOKUP($C26,'NAICS-SOC-CIP x-walk'!C:C, 'NAICS-SOC-CIP x-walk'!H:H) -> 23 | J26: =_xlfn.XLOOKUP(K26,'ACS-NAICS-SOC x-walk'!K:K,'ACS-NAICS-SOC x-walk'!L:L) -> Construction | K26: =_xlfn.XLOOKUP($C26,'NAICS-SOC-CIP x-walk'!$C:$C, 'NAICS-SOC-CIP x-walk'!I:I) -> Construction | L26: =SUMIF(K:K, K26, A:A) -> 4403 | M26: =AVERAGEIF(K:K, K26, A:A) -> 57.934211
A27: 27 | B27: 1-2 | C27: 47-2141 | D27: =VALUE(LEFT(C27,2)) -> 47 | E27: Painters, Construction and Maintenance | F27: {=_xlfn.IFS( AND(D27>=11, D27<=29), "Management, business, science, and arts occupations", AND(D27>=31, D27<=39), "Service occupations", AND(D27>=41, D27<=43), "Sales and office occupations", AND(D27>=51, D27<=53), "Production, transportation, and material moving occupations", AND(D27>=45, D27<=49), "Natural resources, construction, and maintenance occupations", TRUE, "Not applicable to study area" )} -> Natural resources, construction, and maintenance occupations | G27: =SUMIF(F:F, F27, A:A) -> 7339 | H27: =AVERAGEIF(F:F, F27, A:A) -> 59.666667 | I27: =_xlfn.XLOOKUP($C27,'NAICS-SOC-CIP x-walk'!C:C, 'NAICS-SOC-CIP x-walk'!H:H) -> 23 | J27: =_xlfn.XLOOKUP(K27,'ACS-NAICS-SOC x-walk'!K:K,'ACS-NAICS-SOC x-walk'!L:L) -> Construction | K27: =_xlfn.XLOOKUP($C27,'NAICS-SOC-CIP x-walk'!$C:$C, 'NAICS-SOC-CIP x-walk'!I:I) -> Construction | L27: =SUMIF(K:K, K27, A:A) -> 4403 | M27: =AVERAGEIF(K:K, K27, A:A) -> 57.934211
A28: 45 | B28: 1-2 | C28: 47-2142 | D28: =VALUE(LEFT(C28,2)) -> 47 | E28: Paperhangers | F28: {=_xlfn.IFS( AND(D28>=11, D28<=29), "Management, business, science, and arts occupations", AND(D28>=31, D28<=39), "Service occupations", AND(D28>=41, D28<=43), "Sales and office occupations", AND(D28>=51, D28<=53), "Production, transportation, and material moving occupations", AND(D28>=45, D28<=49), "Natural resources, construction, and maintenance occupations", TRUE, "Not applicable to study area" )} -> Natural resources, construction, and maintenance occupations | G28: =SUMIF(F:F, F28, A:A) -> 7339 | H28: =AVERAGEIF(F:F, F28, A:A) -> 59.666667 | I28: =_xlfn.XLOOKUP($C28,'NAICS-SOC-CIP x-walk'!C:C, 'NAICS-SOC-CIP x-walk'!H:H) -> 23 | J28: =_xlfn.XLOOKUP(K28,'ACS-NAICS-SOC x-walk'!K:K,'ACS-NAICS-SOC x-walk'!L:L) -> Construction | K28: =_xlfn.XLOOKUP($C28,'NAICS-SOC-CIP x-walk'!$C:$C, 'NAICS-SOC-CIP x-walk'!I:I) -> Construction | L28: =SUMIF(K:K, K28, A:A) -> 4403 | M28: =AVERAGEIF(K:K, K28, A:A) -> 57.934211
A29: 21 | B29: 1-2 | C29: 47-2151 | D29: =VALUE(LEFT(C29,2)) -> 47 | E29: Pipelayers | F29: {=_xlfn.IFS( AND(D29>=11, D29<=29), "Management, business, science, and arts occupations", AND(D29>=31, D29<=39), "Service occupations", AND(D29>=41, D29<=43), "Sales and office occupations", AND(D29>=51, D29<=53), "Production, transportation, and material moving occupations", AND(D29>=45, D29<=49), "Natural resources, construction, and maintenance occupations", TRUE, "Not applicable to study area" )} -> Natural resources, construction, and maintenance occupations | G29: =SUMIF(F:F, F29, A:A) -> 7339 | H29: =AVERAGEIF(F:F, F29, A:A) -> 59.666667 | I29: =_xlfn.XLOOKUP($C29,'NAICS-SOC-CIP x-walk'!C:C, 'NAICS-SOC-CIP x-walk'!H:H) -> 23 | J29: =_xlfn.XLOOKUP(K29,'ACS-NAICS-SOC x-walk'!K:K,'ACS-NAICS-SOC x-walk'!L:L) -> Construction | K29: =_xlfn.XLOOKUP($C29,'NAICS-SOC-CIP x-walk'!$C:$C, 'NAICS-SOC-CIP x-walk'!I:I) -> Construction | L29: =SUMIF(K:K, K29, A:A) -> 4403 | M29: =AVERAGEIF(K:K, K29, A:A) -> 57.934211
A30: 80 | B30: 3 | C30: 47-2152 | D30: =VALUE(LEFT(C30,2)) -> 47 | E30: Plumbers, Pipefitters, and Steamfitters | F30: {=_xlfn.IFS( AND(D30>=11, D30<=29), "Management, business, science, and arts occupations", AND(D30>=31, D30<=39), "Service occupations", AND(D30>=41, D30<=43), "Sales and office occupations", AND(D30>=51, D30<=53), "Production, transportation, and material moving occupations", AND(D30>=45, D30<=49), "Natural resources, construction, and maintenance occupations", TRUE, "Not applicable to study area" )} -> Natural resources, construction, and maintenance occupations | G30: =SUMIF(F:F, F30, A:A) -> 7339 | H30: =AVERAGEIF(F:F, F30, A:A) -> 59.666667 | I30: =_xlfn.XLOOKUP($C30,'NAICS-SOC-CIP x-walk'!C:C, 'NAICS-SOC-CIP x-walk'!H:H) -> 23 | J30: =_xlfn.XLOOKUP(K30,'ACS-NAICS-SOC x-walk'!K:K,'ACS-NAICS-SOC x-walk'!L:L) -> Construction | K30: =_xlfn.XLOOKUP($C30,'NAICS-SOC-CIP x-walk'!$C:$C, 'NAICS-SOC-CIP x-walk'!I:I) -> Construction | L30: =SUMIF(K:K, K30, A:A) -> 4403 | M30: =AVERAGEIF(K:K, K30, A:A) -> 57.934211
A31: 74 | B31: 3 | C31: 47-2152 | D31: =VALUE(LEFT(C31,2)) -> 47 | E31: Solar Thermal Installers and Technicians | F31: {=_xlfn.IFS( AND(D31>=11, D31<=29), "Management, business, science, and arts occupations", AND(D31>=31, D31<=39), "Service occupations", AND(D31>=41, D31<=43), "Sales and office occupations", AND(D31>=51, D31<=53), "Production, transportation, and material moving occupations", AND(D31>=45, D31<=49), "Natural resources, construction, and maintenance occupations", TRUE, "Not applicable to study area" )} -> Natural resources, construction, and maintenance occupations | G31: =SUMIF(F:F, F31, A:A) -> 7339 | H31: =AVERAGEIF(F:F, F31, A:A) -> 59.666667 | I31: =_xlfn.XLOOKUP($C31,'NAICS-SOC-CIP x-walk'!C:C, 'NAICS-SOC-CIP x-walk'!H:H) -> 23 | J31: =_xlfn.XLOOKUP(K31,'ACS-NAICS-SOC x-walk'!K:K,'ACS-NAICS-SOC x-walk'!L:L) -> Construction | K31: =_xlfn.XLOOKUP($C31,'NAICS-SOC-CIP x-walk'!$C:$C, 'NAICS-SOC-CIP x-walk'!I:I) -> Construction | L31: =SUMIF(K:K, K31, A:A) -> 4403 | M31: =AVERAGEIF(K:K, K31, A:A) -> 57.934211
A32: 33 | B32: 1-2 | C32: 47-2161 | D32: =VALUE(LEFT(C32,2)) -> 47 | E32: Plasterers and Stucco Masons | F32: {=_xlfn.IFS( AND(D32>=11, D32<=29), "Management, business, science, and arts occupations", AND(D32>=31, D32<=39), "Service occupations", AND(D32>=41, D32<=43), "Sales and office occupations", AND(D32>=51, D32<=53), "Production, transportation, and material moving occupations", AND(D32>=45, D32<=49), "Natural resources, construction, and maintenance occupations", TRUE, "Not applicable to study area" )} -> Natural resources, construction, and maintenance occupations | G32: =SUMIF(F:F, F32, A:A) -> 7339 | H32: =AVERAGEIF(F:F, F32, A:A) -> 59.666667 | I32: =_xlfn.XLOOKUP($C32,'NAICS-SOC-CIP x-walk'!C:C, 'NAICS-SOC-CIP x-walk'!H:H) -> 23 | J32: =_xlfn.XLOOKUP(K32,'ACS-NAICS-SOC x-walk'!K:K,'ACS-NAICS-SOC x-walk'!L:L) -> Construction | K32: =_xlfn.XLOOKUP($C32,'NAICS-SOC-CIP x-walk'!$C:$C, 'NAICS-SOC-CIP x-walk'!I:I) -> Construction | L32: =SUMIF(K:K, K32, A:A) -> 4403 | M32: =AVERAGEIF(K:K, K32, A:A) -> 57.934211
A33: 48 | B33: 1-2 | C33: 47-2171 | D33: =VALUE(LEFT(C33,2)) -> 47 | E33: Reinforcing Iron and Rebar Workers | F33: {=_xlfn.IFS( AND(D33>=11, D33<=29), "Management, business, science, and arts occupations", AND(D33>=31, D33<=39), "Service occupations", AND(D33>=41, D33<=43), "Sales and office occupations", AND(D33>=51, D33<=53), "Production, transportation, and material moving occupations", AND(D33>=45, D33<=49), "Natural resources, construction, and maintenance occupations", TRUE, "Not applicable to study area" )} -> Natural resources, construction, and maintenance occupations | G33: =SUMIF(F:F, F33, A:A) -> 7339 | H33: =AVERAGEIF(F:F, F33, A:A) -> 59.666667 | I33: =_xlfn.XLOOKUP($C33,'NAICS-SOC-CIP x-walk'!C:C, 'NAICS-SOC-CIP x-walk'!H:H) -> 23 | J33: =_xlfn.XLOOKUP(K33,'ACS-NAICS-SOC x-walk'!K:K,'ACS-NAICS-SOC x-walk'!L:L) -> Construction | K33: =_xlfn.XLOOKUP($C33,'NAICS-SOC-CIP x-walk'!$C:$C, 'NAICS-SOC-CIP x-walk'!I:I) -> Construction | L33: =SUMIF(K:K, K33, A:A) -> 4403 | M33: =AVERAGEIF(K:K, K33, A:A) -> 57.934211
A34: 71 | B34: 1-2 | C34: 47-2181 | D34: =VALUE(LEFT(C34,2)) -> 47 | E34: Roofers | F34: {=_xlfn.IFS( AND(D34>=11, D34<=29), "Management, business, science, and arts occupations", AND(D34>=31, D34<=39), "Service occupations", AND(D34>=41, D34<=43), "Sales and office occupations", AND(D34>=51, D34<=53), "Production, transportation, and material moving occupations", AND(D34>=45, D34<=49), "Natural resources, construction, and maintenance occupations", TRUE, "Not applicable to study area" )} -> Natural resources, construction, and maintenance occupations | G34: =SUMIF(F:F, F34, A:A) -> 7339 | H34: =AVERAGEIF(F:F, F34, A:A) -> 59.666667 | I34: =_xlfn.XLOOKUP($C34,'NAICS-SOC-CIP x-walk'!C:C, 'NAICS-SOC-CIP x-walk'!H:H) -> 23 | J34: =_xlfn.XLOOKUP(K34,'ACS-NAICS-SOC x-walk'!K:K,'ACS-NAICS-SOC x-walk'!L:L) -> Construction | K34: =_xlfn.XLOOKUP($C34,'NAICS-SOC-CIP x-walk'!$C:$C, 'NAICS-SOC-CIP x-walk'!I:I) -> Construction | L34: =SUMIF(K:K, K34, A:A) -> 4403 | M34: =AVERAGEIF(K:K, K34, A:A) -> 57.934211
A35: 64 | B35: 1-2 | C35: 47-2211 | D35: =VALUE(LEFT(C35,2)) -> 47 | E35: Sheet Metal Workers | F35: {=_xlfn.IFS( AND(D35>=11, D35<=29), "Management, business, science, and arts occupations", AND(D35>=31, D35<=39), "Service occupations", AND(D35>=41, D35<=43), "Sales and office occupations", AND(D35>=51, D35<=53), "Production, transportation, and material moving occupations", AND(D35>=45, D35<=49), "Natural resources, construction, and maintenance occupations", TRUE, "Not applicable to study area" )} -> Natural resources, construction, and maintenance occupations | G35: =SUMIF(F:F, F35, A:A) -> 7339 | H35: =AVERAGEIF(F:F, F35, A:A) -> 59.666667 | I35: =_xlfn.XLOOKUP($C35,'NAICS-SOC-CIP x-walk'!C:C, 'NAICS-SOC-CIP x-walk'!H:H) -> 23 | J35: =_xlfn.XLOOKUP(K35,'ACS-NAICS-SOC x-walk'!K:K,'ACS-NAICS-SOC x-walk'!L:L) -> Construction | K35: =_xlfn.XLOOKUP($C35,'NAICS-SOC-CIP x-walk'!$C:$C, 'NAICS-SOC-CIP x-walk'!I:I) -> Construction | L35: =SUMIF(K:K, K35, A:A) -> 4403 | M35: =AVERAGEIF(K:K, K35, A:A) -> 57.934211
A36: 61 | B36: 1-2 | C36: 47-2221 | D36: =VALUE(LEFT(C36,2)) -> 47 | E36: Structural Iron and Steel Workers | F36: {=_xlfn.IFS( AND(D36>=11, D36<=29), "Management, business, science, and arts occupations", AND(D36>=31, D36<=39), "Service occupations", AND(D36>=41, D36<=43), "Sales and office occupations", AND(D36>=51, D36<=53), "Production, transportation, and material moving occupations", AND(D36>=45, D36<=49), "Natural resources, construction, and maintenance occupations", TRUE, "Not applicable to study area" )} -> Natural resources, construction, and maintenance occupations | G36: =SUMIF(F:F, F36, A:A) -> 7339 | H36: =AVERAGEIF(F:F, F36, A:A) -> 59.666667 | I36: =_xlfn.XLOOKUP($C36,'NAICS-SOC-CIP x-walk'!C:C, 'NAICS-SOC-CIP x-walk'!H:H) -> 23 | J36: =_xlfn.XLOOKUP(K36,'ACS-NAICS-SOC x-walk'!K:K,'ACS-NAICS-SOC x-walk'!L:L) -> Construction | K36: =_xlfn.XLOOKUP($C36,'NAICS-SOC-CIP x-walk'!$C:$C, 'NAICS-SOC-CIP x-walk'!I:I) -> Construction | L36: =SUMIF(K:K, K36, A:A) -> 4403 | M36: =AVERAGEIF(K:K, K36, A:A) -> 57.934211
A37: 74 | B37: 1-2 | C37: 47-2231 | D37: =VALUE(LEFT(C37,2)) -> 47 | E37: Solar Photovoltaic Installers | F37: {=_xlfn.IFS( AND(D37>=11, D37<=29), "Management, business, science, and arts occupations", AND(D37>=31, D37<=39), "Service occupations", AND(D37>=41, D37<=43), "Sales and office occupations", AND(D37>=51, D37<=53), "Production, transportation, and material moving occupations", AND(D37>=45, D37<=49), "Natural resources, construction, and maintenance occupations", TRUE, "Not applicable to study area" )} -> Natural resources, construction, and maintenance occupations | G37: =SUMIF(F:F, F37, A:A) -> 7339 | H37: =AVERAGEIF(F:F, F37, A:A) -> 59.666667 | I37: =_xlfn.XLOOKUP($C37,'NAICS-SOC-CIP x-walk'!C:C, 'NAICS-SOC-CIP x-walk'!H:H) -> 21, 22 | J37: =_xlfn.XLOOKUP(K37,'ACS-NAICS-SOC x-walk'!K:K,'ACS-NAICS-SOC x-walk'!L:L) -> Agriculture, Forestry, Fishing and Hunting, and Mining | K37: =_xlfn.XLOOKUP($C37,'NAICS-SOC-CIP x-walk'!$C:$C, 'NAICS-SOC-CIP x-walk'!I:I) -> Mining, Quarrying, and Oil and Gas Extraction, Utilities | L37: =SUMIF(K:K, K37, A:A) -> 4509 | M37: =AVERAGEIF(K:K, K37, A:A) -> 48.483871
A38: 57 | B38: 1-2 | C38: 47-3011 | D38: =VALUE(LEFT(C38,2)) -> 47 | E38: Helpers--Brickmasons, Blockmasons, Stonemasons, and Tile and Marble Setters | F38: {=_xlfn.IFS( AND(D38>=11, D38<=29), "Management, business, science, and arts occupations", AND(D38>=31, D38<=39), "Service occupations", AND(D38>=41, D38<=43), "Sales and office occupations", AND(D38>=51, D38<=53), "Production, transportation, and material moving occupations", AND(D38>=45, D38<=49), "Natural resources, construction, and maintenance occupations", TRUE, "Not applicable to study area" )} -> Natural resources, construction, and maintenance occupations | G38: =SUMIF(F:F, F38, A:A) -> 7339 | H38: =AVERAGEIF(F:F, F38, A:A) -> 59.666667 | I38: =_xlfn.XLOOKUP($C38,'NAICS-SOC-CIP x-walk'!C:C, 'NAICS-SOC-CIP x-walk'!H:H) -> 23 | J38: =_xlfn.XLOOKUP(K38,'ACS-NAICS-SOC x-walk'!K:K,'ACS-NAICS-SOC x-walk'!L:L) -> Construction | K38: =_xlfn.XLOOKUP($C38,'NAICS-SOC-CIP x-walk'!$C:$C, 'NAICS-SOC-CIP x-walk'!I:I) -> Construction | L38: =SUMIF(K:K, K38, A:A) -> 4403 | M38: =AVERAGEIF(K:K, K38, A:A) -> 57.934211
A39: 61 | B39: 1-2 | C39: 47-3012 | D39: =VALUE(LEFT(C39,2)) -> 47 | E39: Helpers--Carpenters | F39: {=_xlfn.IFS( AND(D39>=11, D39<=29), "Management, business, science, and arts occupations", AND(D39>=31, D39<=39), "Service occupations", AND(D39>=41, D39<=43), "Sales and office occupations", AND(D39>=51, D39<=53), "Production, transportation, and material moving occupations", AND(D39>=45, D39<=49), "Natural resources, construction, and maintenance occupations", TRUE, "Not applicable to study area" )} -> Natural resources, construction, and maintenance occupations | G39: =SUMIF(F:F, F39, A:A) -> 7339 | H39: =AVERAGEIF(F:F, F39, A:A) -> 59.666667 | I39: =_xlfn.XLOOKUP($C39,'NAICS-SOC-CIP x-walk'!C:C, 'NAICS-SOC-CIP x-walk'!H:H) -> 23 | J39: =_xlfn.XLOOKUP(K39,'ACS-NAICS-SOC x-walk'!K:K,'ACS-NAICS-SOC x-walk'!L:L) -> Construction | K39: =_xlfn.XLOOKUP($C39,'NAICS-SOC-CIP x-walk'!$C:$C, 'NAICS-SOC-CIP x-walk'!I:I) -> Construction | L39: =SUMIF(K:K, K39, A:A) -> 4403 | M39: =AVERAGEIF(K:K, K39, A:A) -> 57.934211
A40: 70 | B40: 1-2 | C40: 47-3013 | D40: =VALUE(LEFT(C40,2)) -> 47 | E40: Helpers--Electricians | F40: {=_xlfn.IFS( AND(D40>=11, D40<=29), "Management, business, science, and arts occupations", AND(D40>=31, D40<=39), "Service occupations", AND(D40>=41, D40<=43), "Sales and office occupations", AND(D40>=51, D40<=53), "Production, transportation, and material moving occupations", AND(D40>=45, D40<=49), "Natural resources, construction, and maintenance occupations", TRUE, "Not applicable to study area" )} -> Natural resources, construction, and maintenance occupations | G40: =SUMIF(F:F, F40, A:A) -> 7339 | H40: =AVERAGEIF(F:F, F40, A:A) -> 59.666667 | I40: =_xlfn.XLOOKUP($C40,'NAICS-SOC-CIP x-walk'!C:C, 'NAICS-SOC-CIP x-walk'!H:H) -> 23 | J40: =_xlfn.XLOOKUP(K40,'ACS-NAICS-SOC x-walk'!K:K,'ACS-NAICS-SOC x-walk'!L:L) -> Construction | K40: =_xlfn.XLOOKUP($C40,'NAICS-SOC-CIP x-walk'!$C:$C, 'NAICS-SOC-CIP x-walk'!I:I) -> Construction | L40: =SUMIF(K:K, K40, A:A) -> 4403 | M40: =AVERAGEIF(K:K, K40, A:A) -> 57.934211
A41: 47 | B41: 1-2 | C41: 47-3014 | D41: =VALUE(LEFT(C41,2)) -> 47 | E41: Helpers--Painters, Paperhangers, Plasterers, and Stucco Masons | F41: {=_xlfn.IFS( AND(D41>=11, D41<=29), "Management, business, science, and arts occupations", AND(D41>=31, D41<=39), "Service occupations", AND(D41>=41, D41<=43), "Sales and office occupations", AND(D41>=51, D41<=53), "Production, transportation, and material moving occupations", AND(D41>=45, D41<=49), "Natural resources, construction, and maintenance occupations", TRUE, "Not applicable to study area" )} -> Natural resources, construction, and maintenance occupations | G41: =SUMIF(F:F, F41, A:A) -> 7339 | H41: =AVERAGEIF(F:F, F41, A:A) -> 59.666667 | I41: =_xlfn.XLOOKUP($C41,'NAICS-SOC-CIP x-walk'!C:C, 'NAICS-SOC-CIP x-walk'!H:H) -> 23 | J41: =_xlfn.XLOOKUP(K41,'ACS-NAICS-SOC x-walk'!K:K,'ACS-NAICS-SOC x-walk'!L:L) -> Construction | K41: =_xlfn.XLOOKUP($C41,'NAICS-SOC-CIP x-walk'!$C:$C, 'NAICS-SOC-CIP x-walk'!I:I) -> Construction | L41: =SUMIF(K:K, K41, A:A) -> 4403 | M41: =AVERAGEIF(K:K, K41, A:A) -> 57.934211
A42: 65 | B42: 1-2 | C42: 47-3015 | D42: =VALUE(LEFT(C42,2)) -> 47 | E42: Helpers--Pipelayers, Plumbers, Pipefitters, and Steamfitters | F42: {=_xlfn.IFS( AND(D42>=11, D42<=29), "Management, business, science, and arts occupations", AND(D42>=31, D42<=39), "Service occupations", AND(D42>=41, D42<=43), "Sales and office occupations", AND(D42>=51, D42<=53), "Production, transportation, and material moving occupations", AND(D42>=45, D42<=49), "Natural resources, construction, and maintenance occupations", TRUE, "Not applicable to study area" )} -> Natural resources, construction, and maintenance occupations | G42: =SUMIF(F:F, F42, A:A) -> 7339 | H42: =AVERAGEIF(F:F, F42, A:A) -> 59.666667 | I42: =_xlfn.XLOOKUP($C42,'NAICS-SOC-CIP x-walk'!C:C, 'NAICS-SOC-CIP x-walk'!H:H) -> 23 | J42: =_xlfn.XLOOKUP(K42,'ACS-NAICS-SOC x-walk'!K:K,'ACS-NAICS-SOC x-walk'!L:L) -> Construction | K42: =_xlfn.XLOOKUP($C42,'NAICS-SOC-CIP x-walk'!$C:$C, 'NAICS-SOC-CIP x-walk'!I:I) -> Construction | L42: =SUMIF(K:K, K42, A:A) -> 4403 | M42: =AVERAGEIF(K:K, K42, A:A) -> 57.934211
A43: 48 | B43: 1-2 | C43: 47-3016 | D43: =VALUE(LEFT(C43,2)) -> 47 | E43: Helpers--Roofers | F43: {=_xlfn.IFS( AND(D43>=11, D43<=29), "Management, business, science, and arts occupations", AND(D43>=31, D43<=39), "Service occupations", AND(D43>=41, D43<=43), "Sales and office occupations", AND(D43>=51, D43<=53), "Production, transportation, and material moving occupations", AND(D43>=45, D43<=49), "Natural resources, construction, and maintenance occupations", TRUE, "Not applicable to study area" )} -> Natural resources, construction, and maintenance occupations | G43: =SUMIF(F:F, F43, A:A) -> 7339 | H43: =AVERAGEIF(F:F, F43, A:A) -> 59.666667 | I43: =_xlfn.XLOOKUP($C43,'NAICS-SOC-CIP x-walk'!C:C, 'NAICS-SOC-CIP x-walk'!H:H) -> 23 | J43: =_xlfn.XLOOKUP(K43,'ACS-NAICS-SOC x-walk'!K:K,'ACS-NAICS-SOC x-walk'!L:L) -> Construction | K43: =_xlfn.XLOOKUP($C43,'NAICS-SOC-CIP x-walk'!$C:$C, 'NAICS-SOC-CIP x-walk'!I:I) -> Construction | L43: =SUMIF(K:K, K43, A:A) -> 4403 | M43: =AVERAGEIF(K:K, K43, A:A) -> 57.934211
A44: 81 | B44: 3 | C44: 47-4011 | D44: =VALUE(LEFT(C44,2)) -> 47 | E44: Construction and Building Inspectors | F44: {=_xlfn.IFS( AND(D44>=11, D44<=29), "Management, business, science, and arts occupations", AND(D44>=31, D44<=39), "Service occupations", AND(D44>=41, D44<=43), "Sales and office occupations", AND(D44>=51, D44<=53), "Production, transportation, and material moving occupations", AND(D44>=45, D44<=49), "Natural resources, construction, and maintenance occupations", TRUE, "Not applicable to study area" )} -> Natural resources, construction, and maintenance occupations | G44: =SUMIF(F:F, F44, A:A) -> 7339 | H44: =AVERAGEIF(F:F, F44, A:A) -> 59.666667 | I44: =_xlfn.XLOOKUP($C44,'NAICS-SOC-CIP x-walk'!C:C, 'NAICS-SOC-CIP x-walk'!H:H) -> 23 | J44: =_xlfn.XLOOKUP(K44,'ACS-NAICS-SOC x-walk'!K:K,'ACS-NAICS-SOC x-walk'!L:L) -> Construction | K44: =_xlfn.XLOOKUP($C44,'NAICS-SOC-CIP x-walk'!$C:$C, 'NAICS-SOC-CIP x-walk'!I:I) -> Construction | L44: =SUMIF(K:K, K44, A:A) -> 4403 | M44: =AVERAGEIF(K:K, K44, A:A) -> 57.934211
...

Sheet Outdoors, exposed
A1: Browse by Work Context
A2: Outdoors, Exposed to All Weather Conditions
A4: Context | B4: Job Zone | C4: SOC Occupation Code | D4: SOC 2-Digit Code | E4: SOC 6-Digit Description | F4: ACS Occupation Description | G4: Aggregate ACS Occupation Context Score | H4: ACS Occupation Category Mean Context Score | I4: NAICS Code | J4: ACS Industry Description | K4: NAICS Description | L4: Aggregate Industry Context Score | M4: ACS Industry Category Mean Context Score
A5: 100 | B5: 1-2 | C5: 47-2073 | D5: =VALUE(LEFT(C5,2)) -> 47 | E5: Operating Engineers and Other Construction Equipment Operators | F5: {=_xlfn.IFS( AND(D5>=11, D5<=29), "Management, business, science, and arts occupations", AND(D5>=31, D5<=39), "Service occupations", AND(D5>=41, D5<=43), "Sales and office occupations", AND(D5>=51, D5<=53), "Production, transportation, and material moving occupations", AND(D5>=45, D5<=49), "Natural resources, construction, and maintenance occupations", TRUE, "Not applicable to study area" )} -> Natural resources, construction, and maintenance occupations | G5: =SUMIF(F:F, F5, A:A) -> 8738 | H5: =AVERAGEIF(F:F, F5, A:A) -> 71.04065 | I5: =_xlfn.XLOOKUP($C5,'NAICS-SOC-CIP x-walk'!C:C, 'NAICS-SOC-CIP x-walk'!H:H) -> 23 | J5: =_xlfn.XLOOKUP(K5,'ACS-NAICS-SOC x-walk'!K:K,'ACS-NAICS-SOC x-walk'!L:L) -> Construction | K5: =_xlfn.XLOOKUP($C5,'NAICS-SOC-CIP x-walk'!$C:$C, 'NAICS-SOC-CIP x-walk'!I:I) -> Construction | L5: =SUMIF(K:K, K5, A:A) -> 4669 | M5: =AVERAGEIF(K:K, K5, A:A) -> 61.434211
A6: 100 | B6: 1-2 | C6: 47-2072 | D6: =VALUE(LEFT(C6,2)) -> 47 | E6: Pile Driver Operators | F6: {=_xlfn.IFS( AND(D6>=11, D6<=29), "Management, business, science, and arts occupations", AND(D6>=31, D6<=39), "Service occupations", AND(D6>=41, D6<=43), "Sales and office occupations", AND(D6>=51, D6<=53), "Production, transportation, and material moving occupations", AND(D6>=45, D6<=49), "Natural resources, construction, and maintenance occupations", TRUE, "Not applicable to study area" )} -> Natural resources, construction, and maintenance occupations | G6: =SUMIF(F:F, F6, A:A) -> 8738 | H6: =AVERAGEIF(F:F, F6, A:A) -> 71.04065 | I6: =_xlfn.XLOOKUP($C6,'NAICS-SOC-CIP x-walk'!C:C, 'NAICS-SOC-CIP x-walk'!H:H) -> 23 | J6: =_xlfn.XLOOKUP(K6,'ACS-NAICS-SOC x-walk'!K:K,'ACS-NAICS-SOC x-walk'!L:L) -> Construction | K6: =_xlfn.XLOOKUP($C6,'NAICS-SOC-CIP x-walk'!$C:$C, 'NAICS-SOC-CIP x-walk'!I:I) -> Construction | L6: =SUMIF(K:K, K6, A:A) -> 4669 | M6: =AVERAGEIF(K:K, K6, A:A) -> 61.434211
A7: 100 | B7: 1-2 | C7: 47-2181 | D7: =VALUE(LEFT(C7,2)) -> 47 | E7: Roofers | F7: {=_xlfn.IFS( AND(D7>=11, D7<=29), "Management, business, science, and arts occupations", AND(D7>=31, D7<=39), "Service occupations", AND(D7>=41, D7<=43), "Sales and office occupations", AND(D7>=51, D7<=53), "Production, transportation, and material moving occupations", AND(D7>=45, D7<=49), "Natural resources, construction, and maintenance occupations", TRUE, "Not applicable to study area" )} -> Natural resources, construction, and maintenance occupations | G7: =SUMIF(F:F, F7, A:A) -> 8738 | H7: =AVERAGEIF(F:F, F7, A:A) -> 71.04065 | I7: =_xlfn.XLOOKUP($C7,'NAICS-SOC-CIP x-walk'!C:C, 'NAICS-SOC-CIP x-walk'!H:H) -> 23 | J7: =_xlfn.XLOOKUP(K7,'ACS-NAICS-SOC x-walk'!K:K,'ACS-NAICS-SOC x-walk'!L:L) -> Construction | K7: =_xlfn.XLOOKUP($C7,'NAICS-SOC-CIP x-walk'!$C:$C, 'NAICS-SOC-CIP x-walk'!I:I) -> Construction | L7: =SUMIF(K:K, K7, A:A) -> 4669 | M7: =AVERAGEIF(K:K, K7, A:A) -> 61.434211
A8: 99 | B8: 1-2 | C8: 47-2021 | D8: =VALUE(LEFT(C8,2)) -> 47 | E8: Brickmasons and Blockmasons | F8: {=_xlfn.IFS( AND(D8>=11, D8<=29), "Management, business, science, and arts occupations", AND(D8>=31, D8<=39), "Service occupations", AND(D8>=41, D8<=43), "Sales and office occupations", AND(D8>=51, D8<=53), "Production, transportation, and material moving occupations", AND(D8>=45, D8<=49), "Natural resources, construction, and maintenance occupations", TRUE, "Not applicable to study area" )} -> Natural resources, construction, and maintenance occupations | G8: =SUMIF(F:F, F8, A:A) -> 8738 | H8: =AVERAGEIF(F:F, F8, A:A) -> 71.04065 | I8: =_xlfn.XLOOKUP($C8,'NAICS-SOC-CIP x-walk'!C:C, 'NAICS-SOC-CIP x-walk'!H:H) -> 23 | J8: =_xlfn.XLOOKUP(K8,'ACS-NAICS-SOC x-walk'!K:K,'ACS-NAICS-SOC x-walk'!L:L) -> Construction | K8: =_xlfn.XLOOKUP($C8,'NAICS-SOC-CIP x-walk'!$C:$C, 'NAICS-SOC-CIP x-walk'!I:I) -> Construction | L8: =SUMIF(K:K, K8, A:A) -> 4669 | M8: =AVERAGEIF(K:K, K8, A:A) -> 61.434211
A9: 99 | B9: 1-2 | C9: 47-4051 | D9: =VALUE(LEFT(C9,2)) -> 47 | E9: Highway Maintenance Workers | F9: {=_xlfn.IFS( AND(D9>=11, D9<=29), "Management, business, science, and arts occupations", AND(D9>=31, D9<=39), "Service occupations", AND(D9>=41, D9<=43), "Sales and office occupations", AND(D9>=51, D9<=53), "Production, transportation, and material moving occupations", AND(D9>=45, D9<=49), "Natural resources, construction, and maintenance occupations", TRUE, "Not applicable to study area" )} -> Natural resources, construction, and maintenance occupations | G9: =SUMIF(F:F, F9, A:A) -> 8738 | H9: =AVERAGEIF(F:F, F9, A:A) -> 71.04065 | I9: =_xlfn.XLOOKUP($C9,'NAICS-SOC-CIP x-walk'!C:C, 'NAICS-SOC-CIP x-walk'!H:H) -> 23 | J9: =_xlfn.XLOOKUP(K9,'ACS-NAICS-SOC x-walk'!K:K,'ACS-NAICS-SOC x-walk'!L:L) -> Construction | K9: =_xlfn.XLOOKUP($C9,'NAICS-SOC-CIP x-walk'!$C:$C, 'NAICS-SOC-CIP x-walk'!I:I) -> Construction | L9: =SUMIF(K:K, K9, A:A) -> 4669 | M9: =AVERAGEIF(K:K, K9, A:A) -> 61.434211
